#### 一、函数对象与实例对象
- 函数对象
  将函数作为对象使用时，简称为函数对象
- 实例对象
  new 函数产生的对象，称为实例对象，简称对象

```javascript
function Fn() {}  // Fn 函数
const fn = new Fn()  // Fn 是构造函数，fn 是实例对象（简称为对象）
console.log(Fn.prototype)  // Fn 是函数对象
Fn.call({})  // Fn 是函数对象
$('#app')  // jQuery 函数
$.get('/test') // jQuery 函数对象
```

#### 二、两种类型的回调函数
- 同步回调
  立即执行，全部执行完才会结束，不会被放入到回调队列中
  例如：数组遍历相关的回调函数、`Promise`的`executor`函数

```javascript
// 按顺序先执行完forEach，再输出forEach
const arr = [1, 3, 5];
arr.forEach(item => {
  console.log(item);
})
console.log('forEach');
```

- 异步回调
  不会立即执行，会被放入到回调队列中将来执行
  例如：定时器回调、`ajax`的回调、`Promise`的成功/失败的回调

```javascript
// 即使定时器0秒执行，但因为是异步回调，总是先输出setTimeout
setTimeout(() => {
  console.log('timeout callback');
}, 0)
console.log('setTimeout');
```

#### 三、常见的内置错误
- 错误类型
  - `Error` 所有错误的父类型
  - `ReferenceError` 引用的变量不存在
  - `TypeError` 数据类型不正确或错误
  - `RangeError` 数据值不在其允许的范围内
  - `SyntaxError` 语法错误

```javascript
console.log(a); // ReferenceError: a is not defined
let b;
console.log(b.a); // TypeError: Cannot read property 'a' of undefined
function fn() { fn() };
fn(); // RangeError: Maximum call stack size exceeded
const a = """"; // Uncaught SyntaxError: Unexpected string
```

- 错误处理
  - 捕获错误 `try...catch`
  - 抛出错误 `throw error`

```javascript
try {
  let a
  console.log(a.b)
} catch (err) {
  console.log(err.message)
  console.log(err.stack)
}
console.log('出错之后也能执行')
```
```javascript
function sth () {
  if (Date.now % 2 == 1) {
    console.log('当前时间为奇数，可以执行任务')
  } else {
    throw new Error('当前时间为偶数，不能执行任务')
  }
}
try {
  sth()
} catch (err) {
  alert(err.message)
}
```

- 错误对象
  - `message`属性：错误相关信息
  - `stack`属性：函数调用栈记录信息